import { describe, it, expect, vi, beforeEach } from 'vitest';
import { renderHook, act } from '@testing-library/react';
import { useLogout } from '@/features/auth/hooks/useLogout';
import api from '@/lib/axios';

// Mock the axios instance to control API responses
vi.mock('@/lib/axios', () => ({
    default: {
        post: vi.fn()
    }
}));
const mockedApiPost = vi.mocked(api.post);

describe('useLogout', () => {
    // Clear all mock implementations and call history before each test
    beforeEach(() => {
        mockedApiPost.mockReset();
    });

    // Test Case 1: Successful Logout
    it('should successfully log out a user and update states', async () => {
        const mockResponseData = { message: 'Logout successful' };
        mockedApiPost.mockResolvedValueOnce({ data: mockResponseData, status: 200, statusText: 'OK', headers: {}, config: {} } as any);

        // Render the hook
        const { result } = renderHook(() => useLogout());

        // Assert initial state
        expect(result.current.loading).toBe(false);
        expect(result.current.error).toBeNull();

        let returnedData: any;

        // Act: Call the logout function and await its completion
        await act(async () => {
            returnedData = await result.current.logout();
        });

        // Assert API call
        expect(mockedApiPost).toHaveBeenCalledTimes(1);
        expect(mockedApiPost).toHaveBeenCalledWith('/logout');

        // Assert final state after successful logout
        expect(result.current.loading).toBe(false);
        expect(result.current.error).toBeNull();
        expect(returnedData).toEqual(mockResponseData);
    });

    // Test Case 2: Failed Logout
    it('should handle any error during logout and set the error state', async () => {
        const mockError = new Error('Network error during logout');
        mockedApiPost.mockRejectedValueOnce(mockError);

        // Render the hook
        const { result } = renderHook(() => useLogout());

        // Assert initial state
        expect(result.current.loading).toBe(false);
        expect(result.current.error).toBeNull();

        // Act: Call the logout function and expect it to throw
        await act(async () => {
            await expect(result.current.logout()).rejects.toThrow(mockError);
        });

        // Assert API call
        expect(mockedApiPost).toHaveBeenCalledTimes(1);
        expect(mockedApiPost).toHaveBeenCalledWith('/logout');

        // Assert final state after error
        expect(result.current.loading).toBe(false);
        expect(result.current.error).toBe('Unexpected error occurred');
        // Removed: expect(console.error).toHaveBeenCalledTimes(1);
    });

    // Test Case 3: Error state is cleared on subsequent calls
    it('should clear previous errors on a new logout attempt', async () => {
        const mockInitialError = new Error('First logout attempt failed');
        // Mock the first call to fail
        mockedApiPost.mockRejectedValueOnce(mockInitialError);

        // Render the hook
        const { result } = renderHook(() => useLogout());

        // First call to trigger an error
        await act(async () => {
            await expect(result.current.logout()).rejects.toThrow();
        });
        expect(result.current.error).toBe('Unexpected error occurred');
        expect(result.current.loading).toBe(false);

        // Mock the second call to succeed
        const mockSuccessResponse = { message: 'Logout successful again' };
        mockedApiPost.mockResolvedValueOnce({ data: mockSuccessResponse, status: 200, statusText: 'OK', headers: {}, config: {} } as any);

        // Second call (success this time)
        await act(async () => {
            await result.current.logout();
        });

        // Assert error is cleared and loading is false
        expect(result.current.error).toBeNull(); // Error should be cleared
        expect(result.current.loading).toBe(false);
        expect(mockedApiPost).toHaveBeenCalledTimes(2); // Called twice
    });
});
